Workbook

Sheet MKR Detailed Radiology Events
A1: Accession Number | B1: Modality | C1: Order Procedure | D1: Completed Action Date | E1: Completed Action Time | F1: Completed Hour | G1: Verified Date & Time | H1: Verified Date | I1: Verified Day | J1: WD/WKND | K1: Verified Time | L1: Verified Hour | M1: Verified By | N1: TAT | O1: CPT/HCPCS | P1: wRVU | Q1: TOTAL SHIFT RVU | R1: Hourly wRVU Total | S1: wRVU Rate | T1: TOTAL BONUS
A2: CT20260011185 | B2: CT | C2: CT Abd & Pel wo Oral w IV | D2: 03/01/2026 | E2: 00:00:31 | F2: =HOUR(E2) -> 0 | G2: =H2&K2 -> 03/01/202600:05:48 | H2: 03/01/2026 | I2: 46082 | J2: =IF(OR(WEEKDAY(I2)=1,WEEKDAY(I2)=7),"WE","WD") -> WE | K2: 00:05:48 | L2: =HOUR(K2) -> 0 | M2: Mitsunaga, MD, Myles | N2: =K2-E2 +INT(H2-D2) -> 0.0036689815 | O2: 74177 | P2: =VLOOKUP(O2,'CPT to wRVU'!$A$1:$C$9660,3,FALSE) -> 1.82 | Q2: =SUM(P2:P62) -> 48.41 | R2: =SUM(P2:P19) -> 14.15 | S2: =(R2*65)-550 -> 369.75 | T2: =SUM(S:S) -> 63696.5
A3: CT20260011203 | B3: CT | C3: CT Brain/Head w/o Contrast | D3: 03/01/2026 | E3: 00:08:00 | F3: =HOUR(E3) -> 0 | G3: =H3&K3 -> 03/01/202600:14:44 | H3: 03/01/2026 | I3: 46082 | J3: =IF(OR(WEEKDAY(I3)=1,WEEKDAY(I3)=7),"WE","WD") -> WE | K3: 00:14:44 | L3: =HOUR(K3) -> 0 | M3: Mitsunaga, MD, Myles | N3: =K3-E3 +INT(H3-D3) -> 0.0046759259 | O3: 70450 | P3: =VLOOKUP(O3,'CPT to wRVU'!$A$1:$C$9660,3,FALSE) -> 0.85
A4: CT20260011204 | B4: CT | C4: CT Spine Cervical w/o Contrast | D4: 03/01/2026 | E4: 00:08:00 | F4: =HOUR(E4) -> 0 | G4: =H4&K4 -> 03/01/202600:18:45 | H4: 03/01/2026 | I4: 46082 | J4: =IF(OR(WEEKDAY(I4)=1,WEEKDAY(I4)=7),"WE","WD") -> WE | K4: 00:18:45 | L4: =HOUR(K4) -> 0 | M4: Mitsunaga, MD, Myles | N4: =K4-E4 +INT(H4-D4) -> 0.0074652778 | O4: 72125 | P4: =VLOOKUP(O4,'CPT to wRVU'!$A$1:$C$9660,3,FALSE) -> 1
A5: CT20260011197 | B5: CT | C5: CT Brain/Head w/o Contrast | D5: 03/01/2026 | E5: 00:13:51 | F5: =HOUR(E5) -> 0 | G5: =H5&K5 -> 03/01/202600:25:43 | H5: 03/01/2026 | I5: 46082 | J5: =IF(OR(WEEKDAY(I5)=1,WEEKDAY(I5)=7),"WE","WD") -> WE | K5: 00:25:43 | L5: =HOUR(K5) -> 0 | M5: Mitsunaga, MD, Myles | N5: =K5-E5 +INT(H5-D5) -> 0.0082407407 | O5: 70450 | P5: =VLOOKUP(O5,'CPT to wRVU'!$A$1:$C$9660,3,FALSE) -> 0.85
A6: CT20260011198 | B6: CT | C6: CT Spine Cervical w/o Contrast | D6: 03/01/2026 | E6: 00:13:51 | F6: =HOUR(E6) -> 0 | G6: =H6&K6 -> 03/01/202600:27:50 | H6: 03/01/2026 | I6: 46082 | J6: =IF(OR(WEEKDAY(I6)=1,WEEKDAY(I6)=7),"WE","WD") -> WE | K6: 00:27:50 | L6: =HOUR(K6) -> 0 | M6: Mitsunaga, MD, Myles | N6: =K6-E6 +INT(H6-D6) -> 0.0097106481 | O6: 72125 | P6: =VLOOKUP(O6,'CPT to wRVU'!$A$1:$C$9660,3,FALSE) -> 1
A7: XR20260024129 | B7: XR | C7: XR Chest 2 Views | D7: 03/01/2026 | E7: 00:00:57 | F7: =HOUR(E7) -> 0 | G7: =H7&K7 -> 03/01/202600:43:36 | H7: 03/01/2026 | I7: 46082 | J7: =IF(OR(WEEKDAY(I7)=1,WEEKDAY(I7)=7),"WE","WD") -> WE | K7: 00:43:36 | L7: =HOUR(K7) -> 0 | M7: Mitsunaga, MD, Myles | N7: =K7-E7 +INT(H7-D7) -> 0.029618056 | O7: 71046 | P7: =VLOOKUP(O7,'CPT to wRVU'!$A$1:$C$9660,3,FALSE) -> 0.22
A8: XR20260024137 | B8: XR | C8: XR Spine Lumbar Complete 4+ Views | D8: 03/01/2026 | E8: 00:27:42 | F8: =HOUR(E8) -> 0 | G8: =H8&K8 -> 03/01/202600:43:47 | H8: 03/01/2026 | I8: 46082 | J8: =IF(OR(WEEKDAY(I8)=1,WEEKDAY(I8)=7),"WE","WD") -> WE | K8: 00:43:47 | L8: =HOUR(K8) -> 0 | M8: Mitsunaga, MD, Myles | N8: =K8-E8 +INT(H8-D8) -> 0.011168981 | O8: 72110 | P8: =VLOOKUP(O8,'CPT to wRVU'!$A$1:$C$9660,3,FALSE) -> 0.26
A9: XR20260024134 | B9: XR | C9: XR Knee Complete 4+ Views Right | D9: 03/01/2026 | E9: 00:27:42 | F9: =HOUR(E9) -> 0 | G9: =H9&K9 -> 03/01/202600:44:00 | H9: 03/01/2026 | I9: 46082 | J9: =IF(OR(WEEKDAY(I9)=1,WEEKDAY(I9)=7),"WE","WD") -> WE | K9: 00:44:00 | L9: =HOUR(K9) -> 0 | M9: Mitsunaga, MD, Myles | N9: =K9-E9 +INT(H9-D9) -> 0.011319444 | O9: 73564 | P9: =VLOOKUP(O9,'CPT to wRVU'!$A$1:$C$9660,3,FALSE) -> 0.22
A10: XR20260024133 | B10: XR | C10: XR Chest 2 Views | D10: 03/01/2026 | E10: 00:27:42 | F10: =HOUR(E10) -> 0 | G10: =H10&K10 -> 03/01/202600:44:11 | H10: 03/01/2026 | I10: 46082 | J10: =IF(OR(WEEKDAY(I10)=1,WEEKDAY(I10)=7),"WE","WD") -> WE | K10: 00:44:11 | L10: =HOUR(K10) -> 0 | M10: Mitsunaga, MD, Myles | N10: =K10-E10 +INT(H10-D10) -> 0.011446759 | O10: 71046 | P10: =VLOOKUP(O10,'CPT to wRVU'!$A$1:$C$9660,3,FALSE) -> 0.22
A11: XR20260024128 | B11: XR | C11: XR Wrist Limited 2 Views Left | D11: 03/01/2026 | E11: 00:27:36 | F11: =HOUR(E11) -> 0 | G11: =H11&K11 -> 03/01/202600:44:24 | H11: 03/01/2026 | I11: 46082 | J11: =IF(OR(WEEKDAY(I11)=1,WEEKDAY(I11)=7),"WE","WD") -> WE | K11: 00:44:24 | L11: =HOUR(K11) -> 0 | M11: Mitsunaga, MD, Myles | N11: =K11-E11 +INT(H11-D11) -> 0.011666667 | O11: 73100 | P11: =VLOOKUP(O11,'CPT to wRVU'!$A$1:$C$9660,3,FALSE) -> 0.16
A12: CT20260011209 | B12: CT | C12: CT Brain/Head w/o Contrast | D12: 03/01/2026 | E12: 00:42:26 | F12: =HOUR(E12) -> 0 | G12: =H12&K12 -> 03/01/202600:46:21 | H12: 03/01/2026 | I12: 46082 | J12: =IF(OR(WEEKDAY(I12)=1,WEEKDAY(I12)=7),"WE","WD") -> WE | K12: 00:46:21 | L12: =HOUR(K12) -> 0 | M12: Mitsunaga, MD, Myles | N12: =K12-E12 +INT(H12-D12) -> 0.0027199074 | O12: 70450 | P12: =VLOOKUP(O12,'CPT to wRVU'!$A$1:$C$9660,3,FALSE) -> 0.85
A13: XR20260024132 | B13: XR | C13: XR Chest 1 View Portable | D13: 03/01/2026 | E13: 00:26:00 | F13: =HOUR(E13) -> 0 | G13: =H13&K13 -> 03/01/202600:48:09 | H13: 03/01/2026 | I13: 46082 | J13: =IF(OR(WEEKDAY(I13)=1,WEEKDAY(I13)=7),"WE","WD") -> WE | K13: 00:48:09 | L13: =HOUR(K13) -> 0 | M13: Mitsunaga, MD, Myles | N13: =K13-E13 +INT(H13-D13) -> 0.015381944 | O13: 71045 | P13: =VLOOKUP(O13,'CPT to wRVU'!$A$1:$C$9660,3,FALSE) -> 0.18
A14: CT20260011212 | B14: CT | C14: CT Brain/Head w/o Contrast | D14: 03/01/2026 | E14: 00:46:30 | F14: =HOUR(E14) -> 0 | G14: =H14&K14 -> 03/01/202600:49:36 | H14: 03/01/2026 | I14: 46082 | J14: =IF(OR(WEEKDAY(I14)=1,WEEKDAY(I14)=7),"WE","WD") -> WE | K14: 00:49:36 | L14: =HOUR(K14) -> 0 | M14: Mitsunaga, MD, Myles | N14: =K14-E14 +INT(H14-D14) -> 0.0021527778 | O14: 70450 | P14: =VLOOKUP(O14,'CPT to wRVU'!$A$1:$C$9660,3,FALSE) -> 0.85
... A19: CT20260011188 | B19: CT | C19: CTA Chest | D19: 03/01/2026 | E19: 00:53:31 | F19: =HOUR(E19) -> 0 | G19: =H19&K19 -> 03/01/202600:59:53 | H19: 03/01/2026 | I19: 46082 | J19: =IF(OR(WEEKDAY(I19)=1,WEEKDAY(I19)=7),"WE","WD") -> WE | K19: 00:59:53 | L19: =HOUR(K19) -> 0 | M19: Mitsunaga, MD, Myles | N19: =K19-E19 +INT(H19-D19) -> 0.0044212963 | O19: 71275 | P19: =VLOOKUP(O19,'CPT to wRVU'!$A$1:$C$9660,3,FALSE) -> 1.82
A20: CT20260011190 | B20: CT | C20: CT Abdomen and Pelvis w/ Contrast | D20: 03/01/2026 | E20: 00:53:31 | F20: =HOUR(E20) -> 0 | G20: =H20&K20 -> 03/01/202601:01:12 | H20: 03/01/2026 | I20: 46082 | J20: =IF(OR(WEEKDAY(I20)=1,WEEKDAY(I20)=7),"WE","WD") -> WE | K20: 01:01:12 | L20: =HOUR(K20) -> 1 | M20: Mitsunaga, MD, Myles | N20: =K20-E20 +INT(H20-D20) -> 0.0053356481 | O20: 74177 | P20: =VLOOKUP(O20,'CPT to wRVU'!$A$1:$C$9660,3,FALSE) -> 1.82 | R20: =SUM(P20:P33) -> 7.47
A21: XR20260024144 | B21: XR | C21: XR Chest 1 View Portable | D21: 03/01/2026 | E21: 00:42:17 | F21: =HOUR(E21) -> 0 | G21: =H21&K21 -> 03/01/202601:08:51 | H21: 03/01/2026 | I21: 46082 | J21: =IF(OR(WEEKDAY(I21)=1,WEEKDAY(I21)=7),"WE","WD") -> WE | K21: 01:08:51 | L21: =HOUR(K21) -> 1 | M21: Mitsunaga, MD, Myles | N21: =K21-E21 +INT(H21-D21) -> 0.018449074 | O21: 71045 | P21: =VLOOKUP(O21,'CPT to wRVU'!$A$1:$C$9660,3,FALSE) -> 0.18
A22: XR20260024147 | B22: XR | C22: XR Chest 1 View Portable | D22: 03/01/2026 | E22: 01:05:21 | F22: =HOUR(E22) -> 1 | G22: =H22&K22 -> 03/01/202601:09:23 | H22: 03/01/2026 | I22: 46082 | J22: =IF(OR(WEEKDAY(I22)=1,WEEKDAY(I22)=7),"WE","WD") -> WE | K22: 01:09:23 | L22: =HOUR(K22) -> 1 | M22: Mitsunaga, MD, Myles | N22: =K22-E22 +INT(H22-D22) -> 0.0028009259 | O22: 71045 | P22: =VLOOKUP(O22,'CPT to wRVU'!$A$1:$C$9660,3,FALSE) -> 0.18
A23: XR20260024142 | B23: XR | C23: XR Spine Lumbar Limited 2 or 3 Views | D23: 03/01/2026 | E23: 01:04:44 | F23: =HOUR(E23) -> 1 | G23: =H23&K23 -> 03/01/202601:09:41 | H23: 03/01/2026 | I23: 46082 | J23: =IF(OR(WEEKDAY(I23)=1,WEEKDAY(I23)=7),"WE","WD") -> WE | K23: 01:09:41 | L23: =HOUR(K23) -> 1 | M23: Mitsunaga, MD, Myles | N23: =K23-E23 +INT(H23-D23) -> 0.0034375 | O23: 72100 | P23: =VLOOKUP(O23,'CPT to wRVU'!$A$1:$C$9660,3,FALSE) -> 0.22
A24: XR20260024143 | B24: XR | C24: XR Ankle Complete 3+ Views Right | D24: 03/01/2026 | E24: 01:04:44 | F24: =HOUR(E24) -> 1 | G24: =H24&K24 -> 03/01/202601:10:29 | H24: 03/01/2026 | I24: 46082 | J24: =IF(OR(WEEKDAY(I24)=1,WEEKDAY(I24)=7),"WE","WD") -> WE | K24: 01:10:29 | L24: =HOUR(K24) -> 1 | M24: Mitsunaga, MD, Myles | N24: =K24-E24 +INT(H24-D24) -> 0.0039930556 | O24: 73610 | P24: =VLOOKUP(O24,'CPT to wRVU'!$A$1:$C$9660,3,FALSE) -> 0.17
A25: XR20260024139 | B25: XR | C25: XR Chest 2 Views | D25: 03/01/2026 | E25: 01:06:42 | F25: =HOUR(E25) -> 1 | G25: =H25&K25 -> 03/01/202601:14:26 | H25: 03/01/2026 | I25: 46082 | J25: =IF(OR(WEEKDAY(I25)=1,WEEKDAY(I25)=7),"WE","WD") -> WE | K25: 01:14:26 | L25: =HOUR(K25) -> 1 | M25: Mitsunaga, MD, Myles | N25: =K25-E25 +INT(H25-D25) -> 0.0053703704 | O25: 71046 | P25: =VLOOKUP(O25,'CPT to wRVU'!$A$1:$C$9660,3,FALSE) -> 0.22
A26: CT20260011210 | B26: CT | C26: CTA Neck | D26: 03/01/2026 | E26: 01:08:12 | F26: =HOUR(E26) -> 1 | G26: =H26&K26 -> 03/01/202601:17:26 | H26: 03/01/2026 | I26: 46082 | J26: =IF(OR(WEEKDAY(I26)=1,WEEKDAY(I26)=7),"WE","WD") -> WE | K26: 01:17:26 | L26: =HOUR(K26) -> 1 | M26: Mitsunaga, MD, Myles | N26: =K26-E26 +INT(H26-D26) -> 0.006412037 | O26: 70498 | P26: =VLOOKUP(O26,'CPT to wRVU'!$A$1:$C$9660,3,FALSE) -> 1.75
A27: CT20260011211 | B27: CT | C27: CTA Brain/Head | D27: 03/01/2026 | E27: 01:08:12 | F27: =HOUR(E27) -> 1 | G27: =H27&K27 -> 03/01/202601:17:26 | H27: 03/01/2026 | I27: 46082 | J27: =IF(OR(WEEKDAY(I27)=1,WEEKDAY(I27)=7),"WE","WD") -> WE | K27: 01:17:26 | L27: =HOUR(K27) -> 1 | M27: Mitsunaga, MD, Myles | N27: =K27-E27 +INT(H27-D27) -> 0.006412037 | O27: 70496 | P27: =VLOOKUP(O27,'CPT to wRVU'!$A$1:$C$9660,3,FALSE) -> 1.75
A28: XR20260024148 | B28: XR | C28: XR Chest 2 Views | D28: 03/01/2026 | E28: 01:15:32 | F28: =HOUR(E28) -> 1 | G28: =H28&K28 -> 03/01/202601:26:13 | H28: 03/01/2026 | I28: 46082 | J28: =IF(OR(WEEKDAY(I28)=1,WEEKDAY(I28)=7),"WE","WD") -> WE | K28: 01:26:13 | L28: =HOUR(K28) -> 1 | M28: Mitsunaga, MD, Myles | N28: =K28-E28 +INT(H28-D28) -> 0.0074189815 | O28: 71046 | P28: =VLOOKUP(O28,'CPT to wRVU'!$A$1:$C$9660,3,FALSE) -> 0.22
A29: XR20260024153 | B29: XR | C29: XR Abdomen KUB 1 View | D29: 03/01/2026 | E29: 01:16:48 | F29: =HOUR(E29) -> 1 | G29: =H29&K29 -> 03/01/202601:29:13 | H29: 03/01/2026 | I29: 46082 | J29: =IF(OR(WEEKDAY(I29)=1,WEEKDAY(I29)=7),"WE","WD") -> WE | K29: 01:29:13 | L29: =HOUR(K29) -> 1 | M29: Mitsunaga, MD, Myles | N29: =K29-E29 +INT(H29-D29) -> 0.0086226852 | O29: 74018 | P29: =VLOOKUP(O29,'CPT to wRVU'!$A$1:$C$9660,3,FALSE) -> 0.18
A30: XR20260024149 | B30: XR | C30: XR Chest 2 Views | D30: 03/01/2026 | E30: 01:27:11 | F30: =HOUR(E30) -> 1 | G30: =H30&K30 -> 03/01/202601:31:27 | H30: 03/01/2026 | I30: 46082 | J30: =IF(OR(WEEKDAY(I30)=1,WEEKDAY(I30)=7),"WE","WD") -> WE | K30: 01:31:27 | L30: =HOUR(K30) -> 1 | M30: Mitsunaga, MD, Myles | N30: =K30-E30 +INT(H30-D30) -> 0.002962963 | O30: 71046 | P30: =VLOOKUP(O30,'CPT to wRVU'!$A$1:$C$9660,3,FALSE) -> 0.22
A31: XR20260024154 | B31: XR | C31: XR Chest 1 View Portable | D31: 03/01/2026 | E31: 01:16:48 | F31: =HOUR(E31) -> 1 | G31: =H31&K31 -> 03/01/202601:44:56 | H31: 03/01/2026 | I31: 46082 | J31: =IF(OR(WEEKDAY(I31)=1,WEEKDAY(I31)=7),"WE","WD") -> WE | K31: 01:44:56 | L31: =HOUR(K31) -> 1 | M31: Mitsunaga, MD, Myles | N31: =K31-E31 +INT(H31-D31) -> 0.019537037 | O31: 71045 | P31: =VLOOKUP(O31,'CPT to wRVU'!$A$1:$C$9660,3,FALSE) -> 0.18
A32: XR20260024151 | B32: XR | C32: XR Hand Limited 2 Views Right | D32: 03/01/2026 | E32: 01:42:27 | F32: =HOUR(E32) -> 1 | G32: =H32&K32 -> 03/01/202601:54:07 | H32: 03/01/2026 | I32: 46082 | J32: =IF(OR(WEEKDAY(I32)=1,WEEKDAY(I32)=7),"WE","WD") -> WE | K32: 01:54:07 | L32: =HOUR(K32) -> 1 | M32: Mitsunaga, MD, Myles | N32: =K32-E32 +INT(H32-D32) -> 0.0081018519 | O32: 73120 | P32: =VLOOKUP(O32,'CPT to wRVU'!$A$1:$C$9660,3,FALSE) -> 0.16
A33: XR20260024150 | B33: XR | C33: XR Chest 2 Views | D33: 03/01/2026 | E33: 01:45:38 | F33: =HOUR(E33) -> 1 | G33: =H33&K33 -> 03/01/202601:59:45 | H33: 03/01/2026 | I33: 46082 | J33: =IF(OR(WEEKDAY(I33)=1,WEEKDAY(I33)=7),"WE","WD") -> WE | K33: 01:59:45 | L33: =HOUR(K33) -> 1 | M33: Mitsunaga, MD, Myles | N33: =K33-E33 +INT(H33-D33) -> 0.0098032407 | O33: 71046 | P33: =VLOOKUP(O33,'CPT to wRVU'!$A$1:$C$9660,3,FALSE) -> 0.22
A34: CT20260011221 | B34: CT | C34: CT Brain/Head w/o Contrast | D34: 03/01/2026 | E34: 01:51:03 | F34: =HOUR(E34) -> 1 | G34: =H34&K34 -> 03/01/202602:01:54 | H34: 03/01/2026 | I34: 46082 | J34: =IF(OR(WEEKDAY(I34)=1,WEEKDAY(I34)=7),"WE","WD") -> WE | K34: 02:01:54 | L34: =HOUR(K34) -> 2 | M34: Mitsunaga, MD, Myles | N34: =K34-E34 +INT(H34-D34) -> 0.0075347222 | O34: 70450 | P34: =VLOOKUP(O34,'CPT to wRVU'!$A$1:$C$9660,3,FALSE) -> 0.85 | R34: =SUM(P34:P51) -> 17.09 | S34: =(R34*65)-550 -> 560.85
A35: CT20260011222 | B35: CT | C35: CT Spine Cervical w/o Contrast | D35: 03/01/2026 | E35: 01:51:03 | F35: =HOUR(E35) -> 1 | G35: =H35&K35 -> 03/01/202602:02:13 | H35: 03/01/2026 | I35: 46082 | J35: =IF(OR(WEEKDAY(I35)=1,WEEKDAY(I35)=7),"WE","WD") -> WE | K35: 02:02:13 | L35: =HOUR(K35) -> 2 | M35: Mitsunaga, MD, Myles | N35: =K35-E35 +INT(H35-D35) -> 0.0077546296 | O35: 72125 | P35: =VLOOKUP(O35,'CPT to wRVU'!$A$1:$C$9660,3,FALSE) -> 1
A36: CT20260011180 | B36: CT | C36: CT Brain/Head w/o Contrast | D36: 03/01/2026 | E36: 01:41:15 | F36: =HOUR(E36) -> 1 | G36: =H36&K36 -> 03/01/202602:05:51 | H36: 03/01/2026 | I36: 46082 | J36: =IF(OR(WEEKDAY(I36)=1,WEEKDAY(I36)=7),"WE","WD") -> WE | K36: 02:05:51 | L36: =HOUR(K36) -> 2 | M36: Mitsunaga, MD, Myles | N36: =K36-E36 +INT(H36-D36) -> 0.017083333 | O36: 70450 | P36: =VLOOKUP(O36,'CPT to wRVU'!$A$1:$C$9660,3,FALSE) -> 0.85
A37: CT20260011181 | B37: CT | C37: CTA Neck | D37: 03/01/2026 | E37: 01:41:15 | F37: =HOUR(E37) -> 1 | G37: =H37&K37 -> 03/01/202602:06:59 | H37: 03/01/2026 | I37: 46082 | J37: =IF(OR(WEEKDAY(I37)=1,WEEKDAY(I37)=7),"WE","WD") -> WE | K37: 02:06:59 | L37: =HOUR(K37) -> 2 | M37: Mitsunaga, MD, Myles | N37: =K37-E37 +INT(H37-D37) -> 0.01787037 | O37: 70498 | P37: =VLOOKUP(O37,'CPT to wRVU'!$A$1:$C$9660,3,FALSE) -> 1.75
A38: CT20260011182 | B38: CT | C38: CTA Brain/Head | D38: 03/01/2026 | E38: 01:41:15 | F38: =HOUR(E38) -> 1 | G38: =H38&K38 -> 03/01/202602:06:59 | H38: 03/01/2026 | I38: 46082 | J38: =IF(OR(WEEKDAY(I38)=1,WEEKDAY(I38)=7),"WE","WD") -> WE | K38: 02:06:59 | L38: =HOUR(K38) -> 2 | M38: Mitsunaga, MD, Myles | N38: =K38-E38 +INT(H38-D38) -> 0.01787037 | O38: 70496 | P38: =VLOOKUP(O38,'CPT to wRVU'!$A$1:$C$9660,3,FALSE) -> 1.75
A39: CT20260011217 | B39: CT | C39: CT Abd & Pel wo Oral w IV | D39: 03/01/2026 | E39: 01:51:03 | F39: =HOUR(E39) -> 1 | G39: =H39&K39 -> 03/01/202602:10:32 | H39: 03/01/2026 | I39: 46082 | J39: =IF(OR(WEEKDAY(I39)=1,WEEKDAY(I39)=7),"WE","WD") -> WE | K39: 02:10:32 | L39: =HOUR(K39) -> 2 | M39: Mitsunaga, MD, Myles | N39: =K39-E39 +INT(H39-D39) -> 0.013530093 | O39: 74177 | P39: =VLOOKUP(O39,'CPT to wRVU'!$A$1:$C$9660,3,FALSE) -> 1.82
A40: CT20260011218 | B40: CT | C40: CT Chest W/ Contrast | D40: 03/01/2026 | E40: 01:51:03 | F40: =HOUR(E40) -> 1 | G40: =H40&K40 -> 03/01/202602:10:32 | H40: 03/01/2026 | I40: 46082 | J40: =IF(OR(WEEKDAY(I40)=1,WEEKDAY(I40)=7),"WE","WD") -> WE | K40: 02:10:32 | L40: =HOUR(K40) -> 2 | M40: Mitsunaga, MD, Myles | N40: =K40-E40 +INT(H40-D40) -> 0.013530093 | O40: 76376 | P40: =VLOOKUP(O40,'CPT to wRVU'!$A$1:$C$9660,3,FALSE) -> 0.2
A41: CT20260011218 | B41: CT | C41: CT Chest W/ Contrast | D41: 03/01/2026 | E41: 01:51:03 | F41: =HOUR(E41) -> 1 | G41: =H41&K41 -> 03/01/202602:10:32 | H41: 03/01/2026 | I41: 46082 | J41: =IF(OR(WEEKDAY(I41)=1,WEEKDAY(I41)=7),"WE","WD") -> WE | K41: 02:10:32 | L41: =HOUR(K41) -> 2 | M41: Mitsunaga, MD, Myles | N41: =K41-E41 +INT(H41-D41) -> 0.013530093 | O41: 71260 | P41: =VLOOKUP(O41,'CPT to wRVU'!$A$1:$C$9660,3,FALSE) -> 1.16
A42: CT20260011192 | B42: CT | C42: CT Abd & Pel wo Oral w IV | D42: 03/01/2026 | E42: 01:56:14 | F42: =HOUR(E42) -> 1 | G42: =H42&K42 -> 03/01/202602:13:27 | H42: 03/01/2026 | I42: 46082 | J42: =IF(OR(WEEKDAY(I42)=1,WEEKDAY(I42)=7),"WE","WD") -> WE | K42: 02:13:27 | L42: =HOUR(K42) -> 2 | M42: Mitsunaga, MD, Myles | N42: =K42-E42 +INT(H42-D42) -> 0.011956019 | O42: 74177 | P42: =VLOOKUP(O42,'CPT to wRVU'!$A$1:$C$9660,3,FALSE) -> 1.82
A43: XR20260024131 | B43: XR | C43: XR Chest 2 Views | D43: 03/01/2026 | E43: 02:04:35 | F43: =HOUR(E43) -> 2 | G43: =H43&K43 -> 03/01/202602:15:46 | H43: 03/01/2026 | I43: 46082 | J43: =IF(OR(WEEKDAY(I43)=1,WEEKDAY(I43)=7),"WE","WD") -> WE | K43: 02:15:46 | L43: =HOUR(K43) -> 2 | M43: Mitsunaga, MD, Myles | N43: =K43-E43 +INT(H43-D43) -> 0.0077662037 | O43: 71046 | P43: =VLOOKUP(O43,'CPT to wRVU'!$A$1:$C$9660,3,FALSE) -> 0.22
A44: XR20260024152 | B44: XR | C44: XR Chest 2 Views | D44: 03/01/2026 | E44: 02:03:46 | F44: =HOUR(E44) -> 2 | G44: =H44&K44 -> 03/01/202602:16:00 | H44: 03/01/2026 | I44: 46082 | J44: =IF(OR(WEEKDAY(I44)=1,WEEKDAY(I44)=7),"WE","WD") -> WE | K44: 02:16:00 | L44: =HOUR(K44) -> 2 | M44: Mitsunaga, MD, Myles | N44: =K44-E44 +INT(H44-D44) -> 0.0084953704 | O44: 71046 | P44: =VLOOKUP(O44,'CPT to wRVU'!$A$1:$C$9660,3,FALSE) -> 0.22
...

Sheet CPT to wRVU
A1: CPT | B1: DESCRIPTION | C1: wRVU
A2: 10005 | B2: US guide FNA | C2: 1.46
A3: 19081 | B3: Bx breast stereotactic | C3: 3.29
A4: 19083 | B4: Bx breast lesion us | C4: 3.1
A5: 19283 | B5: Stereotactic placement marker | C5: 2
A6: 19303 | B6: Mast simple complete | C6: 15
A7: 19305 | B7: Mast radical | C7: 17.46
A8: 19306 | B8: Mast rad urban type | C8: 18.13
A9: 19307 | B9: Mast mod rad | C9: 17.99
A10: 19316 | B10: Suspension of breast | C10: 11.09
A11: 19318 | B11: Breast reduction | C11: 16.03
A12: 19325 | B12: Breast augmentation w/implt | C12: 8.12
A13: 19328 | B13: Rmvl intact breast implant | C13: 7.44
... A7345: 99607 | B7345: Mtms by pharm addl 15 min | C7345: 0
A7346: 0001F | B7346: Heart failure composite | C7346: 0
A7347: 0005F | B7347: Osteoarthritis composite | C7347: 0
A7348: 0012F | B7348: Cap bacterial assess | C7348: 0
A7349: 0014F | B7349: Comp preop assess cat surg | C7349: 0
A7350: 0015F | B7350: Melan follow-up complete | C7350: 0
A7351: 0042T | B7351: Ct perfusion w/contrast cbf | C7351: 1.75
A7352: 0054T | B7352: Bone srgry cmptr fluor image | C7352: 0
A7353: 0055T | B7353: Bone srgry cmptr ct/mri imag | C7353: 0
A7354: 0071T | B7354: Us leiomyomata ablate <200 | C7354: 0
A7355: 0072T | B7355: Fcsd us abltj leiomyom>=200 | C7355: 0
A7356: 0075T | B7356: Perq stent/chest vert art | C7356: 0
A7357: 0076T | B7357: S&i stent/chest vert art | C7357: 0
... A9652: A9552 | B9652: Nuc Med Medications | C9652: 0
A9653: CT PET Lung | C9653: 0
A9654: A4641 | C9654: 0
A9655: A9540 | C9655: 0
A9656: FAILED | C9656: 0
A9657: XR CON | B9657: XR BX Consult | C9657: 0
A9658: x | C9658: 0
A9659: 99451 | B9659: XR BX Consult | C9659: 0.28
A9660: 0 | C9660: 0
A9661: IR8 | B9661: IR- All not labeled | C9661: 8

Sheet Ghori Studies Finalized by hour
A1: SUM of wRVU | D1: Verified Hour
A2: Verified By | B2: Verified Date | C2: WD/WKND | D2: 4 | E2: 5 | F2: 6 | G2: 7 | H2: 8 | I2: Grand Total
A3: Ghori, MD, Saima | B3: 03/16/2026 | C3: WD | D3: 7.28 | E3: 12.01 | F3: 3.72 | G3: 5.66 | H3: 2.27 | I3: 30.94
B4: 03/17/2026 | C4: WD | D4: 3.63 | E4: 6.65 | F4: 3.12 | G4: 8.68 | H4: 0.22 | I4: 22.3
B5: 03/18/2026 | C5: WD | D5: 8.07 | E5: 8.13 | F5: 3.21 | G5: 5.29 | H5: 2.52 | I5: 27.22
B6: 03/19/2026 | C6: WD | D6: 4.96 | E6: 10.47 | F6: 0.17 | G6: 9.83 | H6: 1.82 | I6: 27.25
B7: 03/20/2026 | C7: WD | D7: 5.1 | E7: 2.73 | F7: 2.78 | G7: 2.53 | H7: 2.22 | I7: 15.36
B8: 03/23/2026 | C8: WD | D8: 8.11 | E8: 6.84 | F8: 1.4 | G8: 5.39 | H8: 0.22 | I8: 21.96
B9: 03/24/2026 | C9: WD | D9: 6.74 | E9: 3.01 | F9: 11.04 | G9: 5.66 | H9: 1.74 | I9: 28.19
B10: 03/25/2026 | C10: WD | D10: 5.22 | E10: 9.29 | F10: 1.38 | G10: 8.39 | I10: 24.28
B11: 03/26/2026 | C11: WD | D11: 7.77 | E11: 9.61 | F11: 1.74 | G11: 6.78 | I11: 25.9
B12: 03/27/2026 | C12: WD | D12: 4.18 | E12: 7.27 | F12: 5.21 | G12: 4.4 | H12: 1.38 | I12: 22.44
A13: Ghori, MD, Saima Total | D13: 61.06 | E13: 76.01 | F13: 33.77 | G13: 62.61 | H13: 12.39 | I13: 245.84

Sheet DeBevits Studies Finalized by h
A1: SUM of wRVU | E1: Verified Hour
A2: Verified By | B2: Verified Date | C2: WD/WKND | D2: Verified Day | E2: 14 | F2: 15 | G2: 16 | H2: 17 | I2: 19 | J2: 20 | K2: 21 | L2: 22 | M2: 23 | N2: Grand Total
A3: DeBevits, MD, John | B3: 03/26/2026 | C3: WD | D3: 46107 | M3: 0.17 | N3: 0.17
B4: 03/27/2026 | C4: WD | D4: 46108 | E4: 6.11 | F4: 2.59 | G4: 0.52 | H4: 0.28 | I4: 0.22 | J4: 4.02 | K4: 3.85 | L4: 2.6 | N4: 20.19
A5: DeBevits, MD, John Total | E5: 6.11 | F5: 2.59 | G5: 0.52 | H5: 0.28 | I5: 0.22 | J5: 4.02 | K5: 3.85 | L5: 2.6 | M5: 0.17 | N5: 20.36

Sheet Douglas Studies Finalized by ho
A1: SUM of wRVU | E1: Verified Hour
A2: Verified By | B2: Verified Date | C2: WD/WKND | D2: Verified Day | E2: 3 | F2: 4 | G2: 5 | H2: 6 | I2: 7 | J2: 8 | K2: 9 | L2: 10 | M2: 11 | N2: 12 | O2: 13 | P2: 14 | Q2: 15 | R2: 16 | S2: Grand Total
A3: Douglas, MD, David B | B3: 03/01/2026 | C3: WE | D3: 46082 | F3: 4.92 | G3: 9.7 | H3: 9.51 | I3: 6.02 | J3: 11.2 | K3: 6.79 | L3: 5.49 | M3: 8.07 | N3: 2.01 | S3: 63.71
B4: 03/06/2026 | C4: WD | D4: 46087 | F4: 5.97 | G4: 5.19 | H4: 8.57 | I4: 5.1 | S4: 24.83
B5: 03/07/2026 | C5: WE | D5: 46088 | E5: 5.37 | F5: 5.95 | G5: 9.53 | H5: 1.49 | I5: 2.42 | J5: 5.02 | K5: 4.72 | L5: 11.87 | M5: 6.71 | N5: 8.01 | O5: 5.59 | P5: 6.81 | Q5: 10.07 | S5: 83.56
B6: 03/08/2026 | C6: WE | D6: 46089 | E6: 7.09 | F6: 10.52 | G6: 13.82 | H6: 7.36 | I6: 11.76 | J6: 6.14 | K6: 5.64 | L6: 5.03 | M6: 5.85 | N6: 5.72 | O6: 4.13 | P6: 5.79 | Q6: 7.36 | S6: 96.21
B7: 03/14/2026 | C7: WE | D7: 46095 | E7: 10.8 | F7: 7.11 | G7: 12.76 | H7: 5 | I7: 7.61 | J7: 12.76 | K7: 8.76 | L7: 11.75 | M7: 9.38 | N7: 9.1 | O7: 10.98 | P7: 7.49 | Q7: 7.7 | R7: 1.27 | S7: 122.47
B8: 03/15/2026 | C8: WE | D8: 46096 | F8: 11.45 | G8: 6.14 | H8: 9.84 | I8: 5.73 | J8: 7.57 | K8: 6.34 | L8: 7.33 | M8: 4.95 | N8: 10.52 | O8: 5.85 | P8: 6.97 | Q8: 6.37 | R8: 0.18 | S8: 89.24
B9: 03/21/2026 | C9: WE | D9: 46102 | E9: 9.33 | F9: 7.78 | G9: 8.55 | H9: 10.51 | I9: 8.09 | J9: 6.5 | K9: 13.98 | L9: 8.31 | M9: 11.03 | S9: 84.08
B10: 03/22/2026 | C10: WE | D10: 46103 | E10: 11.88 | F10: 8.92 | G10: 4.17 | H10: 4.34 | I10: 9.34 | J10: 11.01 | K10: 9.85 | L10: 8.31 | M10: 6.87 | N10: 0.44 | S10: 75.13
B11: 03/28/2026 | C11: WE | D11: 46109 | E11: 8.84 | F11: 12.52 | G11: 4.02 | H11: 9.22 | I11: 8.24 | J11: 14.47 | K11: 8.46 | L11: 5.53 | M11: 15.72 | N11: 8.05 | O11: 10.75 | P11: 7.98 | Q11: 9.16 | S11: 122.96
B12: 03/29/2026 | C12: WE | D12: 46110 | E12: 7.83 | F12: 13.03 | G12: 8.69 | H12: 9.32 | I12: 8.44 | J12: 11.36 | K12: 10.91 | L12: 13.7 | M12: 9.43 | N12: 12.84 | O12: 8.67 | P12: 4.02 | Q12: 16 | R12: 0.22 | S12: 134.46
B13: 03/31/2026 | C13: WD | D13: 46112 | F13: 8.28 | G13: 11.06 | H13: 8.12 | I13: 11.02 | J13: 3.26 | S13: 41.74
A14: Douglas, MD, David B Total | E14: 61.14 | F14: 96.45 | G14: 93.63 | H14: 83.28 | I14: 83.77 | J14: 89.29 | K14: 75.45 | L14: 77.32 | M14: 78.01 | N14: 56.69 | O14: 45.97 | P14: 39.06 | Q14: 56.66 | R14: 1.67 | S14: 938.39

Sheet Gandhi Studies Finalized by hou
A1: SUM of wRVU | E1: Verified Hour
A2: Verified By | B2: Verified Date | C2: WD/WKND | D2: Verified Day | E2: 4 | F2: 5 | G2: 6 | H2: 7 | I2: 8 | J2: 9 | K2: 10 | L2: 11 | M2: 12 | N2: 13 | O2: 14 | P2: Grand Total
A3: Gandhi, MD, Kabir | B3: 03/09/2026 | C3: WD | D3: 46090 | E3: 7.97 | F3: 9.31 | G3: 4.82 | H3: 4.25 | I3: 5.95 | J3: 3.71 | K3: 3.3 | L3: 5.67 | M3: 6.01 | N3: 4.13 | O3: 0.17 | P3: 55.29
B4: 03/11/2026 | C4: WD | D4: 46092 | E4: 8.03 | F4: 8.06 | G4: 4.59 | H4: 4.83 | I4: 2.89 | J4: 8.66 | K4: 5.04 | L4: 4.59 | M4: 4.76 | N4: 6.97 | O4: 0.74 | P4: 59.16
B5: 03/12/2026 | C5: WD | D5: 46093 | E5: 7.76 | F5: 10.53 | G5: 6.06 | H5: 3.76 | I5: 5.7 | J5: 4.87 | K5: 3.29 | L5: 3.36 | M5: 9.9 | N5: 3.23 | P5: 58.46
B6: 03/13/2026 | C6: WD | D6: 46094 | E6: 8.33 | F6: 4.24 | G6: 2.8 | H6: 5.17 | I6: 3.9 | J6: 4.4 | K6: 5.28 | L6: 4.49 | M6: 10.01 | N6: 8.71 | O6: 0.18 | P6: 57.51
B7: 03/24/2026 | C7: WD | D7: 46105 | I7: 6.44 | J7: 5.93 | K7: 6.22 | L7: 6.93 | M7: 2.47 | N7: 7.65 | P7: 35.64
A8: Gandhi, MD, Kabir Total | E8: 32.09 | F8: 32.14 | G8: 18.27 | H8: 18.01 | I8: 24.88 | J8: 27.57 | K8: 23.13 | L8: 25.04 | M8: 33.15 | N8: 30.69 | O8: 1.09 | P8: 266.06

Sheet Lomis Studies Finalized by hour
A1: SUM of wRVU | E1: Verified Hour
A2: Verified By | B2: Verified Date | C2: WD/WKND | D2: Verified Day | E2: 4 | F2: 5 | G2: 6 | H2: 7 | I2: 14 | J2: 15 | K2: 16 | L2: 17 | M2: 18 | N2: 19 | O2: 20 | P2: 21 | Q2: Grand Total
A3: Lomis, MD, Nick | B3: 03/06/2026 | C3: WD | D3: 46087 | I3: 25.72 | J3: 12.74 | K3: 21.2 | Q3: 59.66
B4: 03/10/2026 | C4: WD | D4: 46091 | E4: 21.05 | F4: 11.52 | G4: 1.27 | H4: 13.5 | Q4: 47.34
B5: 03/15/2026 | C5: WE | D5: 46096 | I5: 14.37 | J5: 10.69 | K5: 11.16 | L5: 7.74 | Q5: 43.96
B6: 03/20/2026 | C6: WD | D6: 46101 | I6: 16.12 | J6: 15.07 | K6: 11.99 | Q6: 43.18
B7: 03/28/2026 | C7: WE | D7: 46109 | I7: 11.9 | J7: 11.88 | K7: 10.73 | L7: 13.49 | M7: 9.72 | N7: 10 | O7: 9.23 | P7: 7.38 | Q7: 84.33
B8: 03/29/2026 | C8: WE | D8: 46110 | I8: 11.05 | J8: 15.19 | K8: 5.18 | L8: 9.48 | M8: 8.23 | N8: 10.27 | O8: 12.87 | P8: 7.68 | Q8: 79.95
B9: 03/30/2026 | C9: WD | D9: 46111 | I9: 14.77 | J9: 14.35 | K9: 9.17 | L9: 7.24 | M9: 11.03 | N9: 13.05 | O9: 10.17 | P9: 4.44 | Q9: 84.22
B10: 03/31/2026 | C10: WD | D10: 46112 | I10: 8.71 | J10: 17.02 | K10: 14.18 | L10: 6.12 | M10: 6.02 | N10: 2.71 | O10: 4.04 | P10: 13.25 | Q10: 72.05
A11: Lomis, MD, Nick Total | E11: 21.05 | F11: 11.52 | G11: 1.27 | H11: 13.5 | I11: 102.64 | J11: 96.94 | K11: 83.61 | L11: 44.07 | M11: 35 | N11: 36.03 | O11: 36.31 | P11: 32.75 | Q11: 514.69

Sheet Masotto Studies Finalized by ho
A1: SUM of wRVU | E1: Verified Hour
A2: Verified By | B2: Verified Date | C2: WD/WKND | D2: Verified Day | E2: 7 | F2: 8 | G2: 9 | H2: 10 | I2: 11 | J2: 12 | K2: 13 | L2: 14 | M2: 15 | N2: 16 | O2: 17 | P2: 18 | Q2: 19 | R2: 20 | S2: Grand Total
A3: Masotto, MD, Mark | B3: 03/01/2026 | C3: WE | D3: 46082 | K3: 0.85 | L3: 11.05 | M3: 19.66 | N3: 8.19 | O3: 8.57 | P3: 9.83 | Q3: 22.71 | R3: 7.72 | S3: 88.58
B4: 03/02/2026 | C4: WD | D4: 46083 | E4: 4.88 | F4: 18.32 | G4: 21.52 | H4: 16.79 | I4: 15.68 | J4: 12.29 | K4: 14.78 | L4: 15.71 | M4: 19.9 | N4: 21.57 | S4: 161.44
B5: 03/03/2026 | C5: WD | D5: 46084 | E5: 6.01 | F5: 20.04 | G5: 15.04 | H5: 24.14 | I5: 14.74 | J5: 17.89 | K5: 20.06 | L5: 16.65 | M5: 13.6 | N5: 6.97 | S5: 155.14
B6: 03/04/2026 | C6: WD | D6: 46085 | E6: 1.48 | F6: 12.74 | G6: 17.5 | H6: 19.64 | I6: 18.59 | J6: 12.42 | K6: 19.01 | L6: 19.77 | M6: 13.64 | N6: 14.84 | S6: 149.63
B7: 03/06/2026 | C7: WD | D7: 46087 | P7: 3.25 | S7: 3.25
B8: 03/10/2026 | C8: WD | D8: 46091 | E8: 2.76 | F8: 14.85 | G8: 13.48 | H8: 17.4 | I8: 17.61 | J8: 13.11 | K8: 26.89 | L8: 17.05 | M8: 17.53 | N8: 12.94 | S8: 153.62
B9: 03/11/2026 | C9: WD | D9: 46092 | N9: 4.26 | S9: 4.26
A10: Masotto, MD, Mark Total | E10: 15.13 | F10: 65.95 | G10: 67.54 | H10: 77.97 | I10: 66.62 | J10: 55.71 | K10: 81.59 | L10: 80.23 | M10: 84.33 | N10: 68.77 | O10: 8.57 | P10: 13.08 | Q10: 22.71 | R10: 7.72 | S10: 715.92

Sheet Mautone Studies Finalized by ho
A1: SUM of wRVU | E1: Verified Hour
A2: Verified By | B2: Verified Date | C2: WD/WKND | D2: Verified Day | E2: 4 | F2: 5 | G2: 6 | H2: 7 | I2: 8 | J2: Grand Total
A3: Mautone, DO, Louis | B3: 03/02/2026 | C3: WD | D3: 46083 | E3: 6.85 | F3: 6.65 | G3: 8.61 | H3: 2.34 | I3: 1.82 | J3: 26.27
B4: 03/03/2026 | C4: WD | D4: 46084 | E4: 7.91 | F4: 6.66 | G4: 8.52 | H4: 8.47 | I4: 0.22 | J4: 31.78
B5: 03/04/2026 | C5: WD | D5: 46085 | E5: 7.27 | F5: 9.78 | G5: 11.26 | H5: 11.84 | I5: 1.18 | J5: 41.33
B6: 03/05/2026 | C6: WD | D6: 46086 | E6: 9.43 | F6: 8.94 | G6: 7.16 | H6: 5.79 | J6: 31.32
A7: Mautone, DO, Louis Total | E7: 31.46 | F7: 32.03 | G7: 35.55 | H7: 28.44 | I7: 3.22 | J7: 130.7

Sheet Mitsunaga Studies Finalized by 
A1: SUM of wRVU | E1: Verified Hour
A2: Verified By | B2: Verified Date | C2: WD/WKND | D2: Verified Day | E2: 0 | F2: 1 | G2: 2 | H2: 3 | I2: 4 | J2: 12 | K2: 13 | L2: 14 | M2: 15 | N2: 16 | O2: 22 | P2: 23 | Q2: Grand Total
A3: Mitsunaga, MD, Myles | B3: 03/01/2026 | C3: WE | D3: 46082 | E3: 14.15 | F3: 7.47 | G3: 17.09 | H3: 9.54 | I3: 0.16 | J3: 7.78 | K3: 5.77 | L3: 2.17 | M3: 3.78 | O3: 0.22 | P3: 3.55 | Q3: 71.68
B4: 03/02/2026 | C4: WD | D4: 46083 | E4: 10.36 | F4: 6.04 | G4: 13.29 | H4: 0.81 | I4: 1.82 | P4: 3 | Q4: 35.32
B5: 03/03/2026 | C5: WD | D5: 46084 | E5: 16.24 | F5: 9.3 | G5: 11.54 | H5: 7.21 | I5: 0.22 | P5: 3.42 | Q5: 47.93
B6: 03/04/2026 | C6: WD | D6: 46085 | E6: 18.85 | F6: 10.13 | G6: 11.72 | H6: 5.86 | I6: 0.85 | P6: 2.55 | Q6: 49.96
B7: 03/05/2026 | C7: WD | D7: 46086 | E7: 10.44 | F7: 7.95 | G7: 5.17 | H7: 10.05 | I7: 1.16 | P7: 2.15 | Q7: 36.92
B8: 03/06/2026 | C8: WD | D8: 46087 | E8: 7.84 | F8: 0.36 | G8: 4.22 | H8: 4.85 | I8: 0.38 | P8: 1.42 | Q8: 19.07
B9: 03/07/2026 | C9: WE | D9: 46088 | E9: 6.35 | F9: 8.25 | G9: 10.56 | H9: 1.82 | P9: 1.64 | Q9: 28.62
B10: 03/08/2026 | C10: WE | D10: 46089 | E10: 7.76 | F10: 6.5 | H10: 1.22 | P10: 2.34 | Q10: 17.82
B11: 03/09/2026 | C11: WD | D11: 46090 | E11: 9.87 | F11: 11.45 | G11: 6.35 | H11: 3.09 | I11: 0.59 | P11: 2.23 | Q11: 33.58
B12: 03/10/2026 | C12: WD | D12: 46091 | E12: 10.43 | F12: 9.28 | G12: 12.52 | H12: 15.29 | I12: 1.82 | P12: 2.3 | Q12: 51.64
B13: 03/11/2026 | C13: WD | D13: 46092 | E13: 11.89 | F13: 6.12 | G13: 4.92 | H13: 5.3 | I13: 1.59 | P13: 3.52 | Q13: 33.34
B14: 03/12/2026 | C14: WD | D14: 46093 | E14: 8.72 | F14: 9.86 | G14: 12.84 | H14: 4.26 | I14: 0.85 | P14: 4.41 | Q14: 40.94
B15: 03/13/2026 | C15: WD | D15: 46094 | E15: 14.08 | F15: 15.89 | G15: 11.26 | H15: 9.15 | I15: 0.18 | P15: 2.06 | Q15: 52.62
B16: 03/14/2026 | C16: WE | D16: 46095 | E16: 14.35 | F16: 14.36 | G16: 3.31 | H16: 1.38 | P16: 1.76 | Q16: 35.16
B17: 03/15/2026 | C17: WE | D17: 46096 | E17: 11.86 | F17: 9.08 | G17: 7 | H17: 10.66 | I17: 0.16 | P17: 4.64 | Q17: 43.4
B18: 03/16/2026 | C18: WD | D18: 46097 | E18: 18.15 | F18: 14.5 | G18: 6.05 | H18: 2.07 | I18: 0.22 | P18: 2.57 | Q18: 43.56
B19: 03/17/2026 | C19: WD | D19: 46098 | E19: 11.2 | F19: 8.73 | G19: 10.34 | H19: 5.33 | I19: 0.23 | P19: 3.63 | Q19: 39.46
B20: 03/18/2026 | C20: WD | D20: 46099 | E20: 12.55 | F20: 12.19 | G20: 15.05 | H20: 13.77 | I20: 0.18 | P20: 4.7 | Q20: 58.44
B21: 03/19/2026 | C21: WD | D21: 46100 | E21: 14.31 | F21: 7.73 | G21: 9.5 | H21: 14.14 | I21: 0.22 | P21: 2.76 | Q21: 48.66
B22: 03/20/2026 | C22: WD | D22: 46101 | E22: 11.97 | F22: 9.43 | G22: 15.09 | H22: 8.76 | I22: 0.18 | P22: 0.89 | Q22: 46.32
B23: 03/21/2026 | C23: WE | D23: 46102 | E23: 7.22 | F23: 10.27 | G23: 17.1 | H23: 1.82 | J23: 3.37 | K23: 3.9 | L23: 3.29 | M23: 2.22 | N23: 0.18 | P23: 5.61 | Q23: 54.98
B24: 03/22/2026 | C24: WE | D24: 46103 | E24: 5.06 | F24: 15.72 | G24: 12.15 | H24: 1.22 | J24: 3.2 | K24: 3.72 | L24: 4.37 | M24: 2.63 | N24: 0.22 | P24: 2.76 | Q24: 51.05
B25: 03/23/2026 | C25: WD | D25: 46104 | E25: 13.81 | F25: 3.36 | G25: 7.28 | H25: 11.16 | I25: 0.22 | P25: 2.14 | Q25: 37.97
B26: 03/24/2026 | C26: WD | D26: 46105 | E26: 16.3 | F26: 8.46 | G26: 10.62 | H26: 4.51 | I26: 0.18 | P26: 2.06 | Q26: 42.13
B27: 03/25/2026 | C27: WD | D27: 46106 | E27: 8.95 | F27: 9.07 | G27: 15.52 | H27: 13.77 | I27: 1.82 | P27: 2.05 | Q27: 51.18
B28: 03/26/2026 | C28: WD | D28: 46107 | E28: 11.72 | F28: 10.47 | G28: 4.86 | P28: 2.68 | Q28: 29.73
B29: 03/27/2026 | C29: WD | D29: 46108 | E29: 12.37 | F29: 8.34 | G29: 9.93 | H29: 17.4 | I29: 1.82 | P29: 0.74 | Q29: 50.6
B30: 03/28/2026 | C30: WE | D30: 46109 | E30: 11.25 | F30: 12.82 | G30: 9.01 | H30: 1.82 | P30: 2.09 | Q30: 36.99
B31: 03/29/2026 | C31: WE | D31: 46110 | E31: 13.25 | F31: 17.23 | G31: 9.91 | H31: 3.18 | P31: 2.45 | Q31: 46.02
B32: 03/30/2026 | C32: WD | D32: 46111 | E32: 12.52 | F32: 6.67 | G32: 16.74 | H32: 10.2 | I32: 0.85 | P32: 4.24 | Q32: 51.22
B33: 03/31/2026 | C33: WD | D33: 46112 | E33: 9.8 | F33: 15.33 | G33: 12.37 | H33: 6 | I33: 0.18 | P33: 2.63 | Q33: 46.31
A34: Mitsunaga, MD, Myles Total | E34: 363.62 | F34: 302.36 | G34: 313.31 | H34: 205.64 | I34: 15.88 | J34: 14.35 | K34: 13.39 | L34: 9.83 | M34: 8.63 | N34: 0.4 | O34: 0.22 | P34: 84.99 | Q34: 1332.62

Sheet Vaccaro Studies Finalized by ho
A1: SUM of wRVU | E1: Verified Hour
A2: Verified By | B2: Verified Date | C2: WD/WKND | D2: Verified Day | E2: 4 | F2: 5 | G2: 6 | H2: 7 | I2: Grand Total
A3: Vaccaro, MD, Jonathan | B3: 03/30/2026 | C3: WD | D3: 46111 | E3: 10.46 | F3: 11.6 | G3: 12.28 | H3: 11.18 | I3: 45.52
A4: Vaccaro, MD, Jonathan Total | E4: 10.46 | F4: 11.6 | G4: 12.28 | H4: 11.18 | I4: 45.52
